0x1800342e0 PyInit__drive 1
